# 🔧 用户ID映射修复 - 关键问题解决

## 🚨 发现的关键问题

通过仔细检查代码，发现了一个**非常重要的用户ID映射问题**，这很可能是导致验证失败的根本原因！

## 🔍 问题分析

### 1. **训练时的正确映射**：
```python
# 在 utils/data_loader.py 中
def _scan_data(self):
    # 扫描 ID_1, ID_2, ID_3, ..., ID_31 目录
    all_users = sorted([1, 2, 3, ..., 31])  # 假设所有用户都存在
    user_to_idx = {1: 0, 2: 1, 3: 2, ..., 31: 30}  # 正确的映射

def __getitem__(self, idx):
    user_id = self.user_labels[idx]      # 真实ID: 1, 2, 3, ..., 31
    user_idx = self.user_to_idx[user_id] # 索引: 0, 1, 2, ..., 30
    return {'user_idx': user_idx}        # 训练时使用正确的索引
```

### 2. **推理时的错误映射**：
```python
# 在 inference/generate_training_style.py 中 (修复前)
user_idx = user_id - 1 if user_id > 0 else user_id  # 简单的 -1 映射！❌
```

### 3. **问题场景举例**：

假设你的数据目录结构是：
```
/kaggle/input/dataset/
├── ID_1/    # 用户1
├── ID_3/    # 用户3 (注意：没有ID_2)
├── ID_5/    # 用户5
├── ID_10/   # 用户10
└── ID_31/   # 用户31
```

**训练时的正确映射**：
```python
all_users = [1, 3, 5, 10, 31]  # 排序后的实际用户列表
user_to_idx = {
    1: 0,   # 用户1 → 索引0
    3: 1,   # 用户3 → 索引1
    5: 2,   # 用户5 → 索引2
    10: 3,  # 用户10 → 索引3
    31: 4   # 用户31 → 索引4
}
```

**推理时的错误映射**：
```python
user_id=1  → user_idx=0   ✅ 正确
user_id=3  → user_idx=2   ❌ 错误！应该是1
user_id=5  → user_idx=4   ❌ 错误！应该是2
user_id=10 → user_idx=9   ❌ 错误！应该是3
user_id=31 → user_idx=30  ❌ 错误！应该是4
```

## 🔧 修复方案

### 修复后的推理脚本逻辑：
```python
# 新增：获取训练时的用户ID映射
def get_correct_user_mapping(data_dir):
    all_users = []
    for user_dir in Path(data_dir).iterdir():
        if user_dir.is_dir() and user_dir.name.startswith('ID_'):
            user_id = int(user_dir.name.split('_')[1])
            all_users.append(user_id)
    
    all_users = sorted(all_users)  # 与训练时相同的排序
    user_id_to_idx = {user_id: idx for idx, user_id in enumerate(all_users)}
    return user_id_to_idx

# 使用正确的映射
user_idx = user_id_to_idx[user_id]  # 正确的映射！✅
```

## 🚀 修复后的使用方法

### 新的推理命令：
```bash
python inference/generate_training_style.py \
    --vae_path "/kaggle/input/final-model" \
    --unet_path "/kaggle/input/diffusion-final-model" \
    --condition_encoder_path "/kaggle/input/diffusion-final-model/condition_encoder.pt" \
    --num_users 31 \
    --user_ids 1 \
    --num_images_per_user 16 \
    --output_dir "/kaggle/working/generated_images" \
    --data_dir "/kaggle/input/dataset"  # 🔑 关键：提供数据目录
```

### 新的验证命令：
```bash
python validation/improved_single_user_validation.py \
    --target_user_id 1 \
    --real_data_root "/kaggle/input/dataset" \
    --generate_images \
    --vae_path "/kaggle/input/final-model" \
    --unet_path "/kaggle/input/diffusion-final-model" \
    --condition_encoder_path "/kaggle/input/diffusion-final-model/condition_encoder.pt" \
    --epochs 25 \
    --batch_size 32 \
    --max_samples_per_class 1000 \
    --guidance_scale 15.0
```

## 📊 修复效果预期

### 修复前的问题：
- 成功率: 0.0%
- 平均置信度: 0.352
- 原因: 条件编码器接收到错误的用户索引

### 修复后的预期：
- 成功率: 应该显著提升 (>60%)
- 平均置信度: 应该显著提升 (>0.6)
- 原因: 条件编码器接收到正确的用户索引

## 🔍 调试信息

修复后的脚本会输出详细的映射信息：
```
🔍 获取训练时的用户ID映射...
  找到 5 个用户: [1, 3, 5, 10, 31]
  用户ID映射: {1: 0, 3: 1, 5: 2, 10: 3, 31: 4}

Generating 16 images for user 1...
  用户 1 → 索引 0
```

## 💡 为什么这个问题很隐蔽

1. **训练时没问题**：因为数据加载器和条件编码器都使用相同的映射逻辑
2. **推理时有问题**：因为推理脚本使用了简化的映射假设
3. **症状不明显**：模型仍然会生成图像，但条件控制失效
4. **验证才发现**：只有通过分类器验证才能发现条件控制失效

## 🎯 关键要点

### 这个修复解决了：
1. **条件控制失效**：现在条件编码器会接收到正确的用户索引
2. **用户特征缺失**：生成的图像应该包含正确的用户特征
3. **验证失败**：分类器验证应该显著改善

### 这解释了为什么：
1. **训练时生成样本正常**：因为使用了正确的映射
2. **独立推理时效果差**：因为使用了错误的映射
3. **验证成功率为0**：因为生成的图像没有正确的用户特征

## 🚀 立即测试

现在重新运行验证，应该会看到显著改善：

```bash
python validation/improved_single_user_validation.py \
    --target_user_id 1 \
    --real_data_root "/kaggle/input/dataset" \
    --generate_images \
    --vae_path "/kaggle/input/final-model" \
    --unet_path "/kaggle/input/diffusion-final-model" \
    --condition_encoder_path "/kaggle/input/diffusion-final-model/condition_encoder.pt" \
    --epochs 25 \
    --batch_size 32 \
    --max_samples_per_class 1000 \
    --guidance_scale 15.0
```

这个修复应该是解决问题的关键！🎨
